#VRML_SIM R2023b utf8

EXTERNPROTO "https://raw.githubusercontent.com/cyberbotics/webots/R2023b/projects/objects/backgrounds/protos/TexturedBackground.proto"
EXTERNPROTO "https://raw.githubusercontent.com/cyberbotics/webots/R2023b/projects/objects/backgrounds/protos/TexturedBackgroundLight.proto"
EXTERNPROTO "https://raw.githubusercontent.com/cyberbotics/webots/R2023b/projects/objects/floors/protos/RectangleArena.proto"

WorldInfo {
  info [
    "Example use of a rotating Lidar in point-cloud mode."
  ]
  title "Lidar Point-Cloud"
  basicTimeStep 8
  lineScale 0.15
}
Viewpoint {
  orientation 0.3577334978509149 -0.15285553968094256 -0.9212284887606318 3.8915918456119853
  position 1.9466126401845685 -3.356782202477625 5.0406904840075075
  follow "MyBot"
}
TexturedBackground {
}
TexturedBackgroundLight {
}
RectangleArena {
  floorSize 10 10
  wallThickness 0.5
  wallHeight 1.4
}
DEF GREEN_OBJECT1 Solid {
  translation 3.0466 1.1512 0.2
  rotation 0 0 1 3.13621
  children [
    DEF BOX_SHAPE Shape {
      appearance PBRAppearance {
        baseColor 0 1 0
        roughness 0.2189099510000001
        metalness 0
      }
      geometry Box {
        size 0.4 0.8 0.4
      }
    }
  ]
  name "green object 1"
  boundingObject USE BOX_SHAPE
}
DEF GREEN_OBJECT2 Solid {
  translation 3.0576 0.5008 0.56
  rotation 0 0 1 3.13621
  children [
    USE BOX_SHAPE
  ]
  name "green object 2"
  boundingObject USE BOX_SHAPE
}
DEF GREEN_OBJECT3 Solid {
  translation 3.0481 -0.2017 0.2
  rotation 0 0 1 3.13621
  children [
    USE BOX_SHAPE
  ]
  name "green object 3"
  boundingObject USE BOX_SHAPE
}
DEF GREEN_OBJECT4 Solid {
  translation 3.0766 -2.9043 0.3
  rotation 0 0 1 3.13621
  children [
    Transform {
      scale 1.6009 1.6009 1.6009
      children [
        USE BOX_SHAPE
      ]
    }
  ]
  name "green object 4"
  boundingObject USE BOX_SHAPE
}
DEF GREEN_OBJECT5 Solid {
  translation -2.7202 -1.5167 0.3
  rotation 0 0 1 -2.623375
  children [
    Transform {
      scale 1.80916 1.80916 1.80916
      children [
        USE BOX_SHAPE
      ]
    }
  ]
  name "green object 5"
  boundingObject USE BOX_SHAPE
}
DEF BLUE_OBJECT1 Solid {
  translation 1.7069 3.5213 0.37
  rotation -0.6958897140492328 0.5078077913347121 0.5078077913347121 -1.925669
  children [
    Transform {
      scale 1.63795 1.63795 1.63795
      children [
        DEF SPHERE_SHAPE Shape {
          appearance PBRAppearance {
            baseColor 0 0 1
            roughness 0.519341125
            metalness 0
          }
          geometry Sphere {
            radius 0.35
            subdivision 2
          }
        }
      ]
    }
  ]
  name "blue object 1"
  boundingObject USE SPHERE_SHAPE
}
DEF BLUE_OBJECT2 Solid {
  translation 1.1936 -1.2416 0.27
  rotation -0.6958897140492328 0.5078077913347121 0.5078077913347121 -1.925669
  children [
    Transform {
      scale 1.66973 1.66973 1.66973
      children [
        USE SPHERE_SHAPE
      ]
    }
  ]
  name "blue object 2"
  boundingObject USE SPHERE_SHAPE
}
DEF BLUE_OBJECT3 Solid {
  translation -2.8124 1.527 0.27
  rotation -0.5652341910457974 0.4124661394111039 0.714410241466416 -1.592006
  children [
    Transform {
      scale 1.64056 1.64056 1.64056
      children [
        USE SPHERE_SHAPE
      ]
    }
  ]
  name "blue object 3"
  boundingObject USE SPHERE_SHAPE
}
DEF PINK_OBJECT1 Solid {
  translation 1.8848 1.5955 0.55
  children [
    Transform {
      scale 1.46599 1.46599 1.46599
      children [
        DEF CYLINDER_SHAPE Shape {
          appearance PBRAppearance {
            baseColor 1 0.1 0.3
            roughness 0.16827074099999995
            metalness 0
          }
          geometry Cylinder {
            height 0.8
            radius 0.3
            subdivision 20
          }
        }
      ]
    }
  ]
  name "pink object 1"
  boundingObject USE CYLINDER_SHAPE
}
DEF PINK_OBJECT2 Solid {
  translation -0.3676 3.1247 0.47
  children [
    Transform {
      scale 1.34833 1.34833 1.34833
      children [
        USE CYLINDER_SHAPE
      ]
    }
  ]
  name "pink object 2"
  boundingObject USE CYLINDER_SHAPE
}
DEF PINK_OBJECT3 Solid {
  translation -0.5829 -2.5176 0.54
  children [
    Transform {
      scale 1.51649 1.51649 1.51649
      children [
        USE CYLINDER_SHAPE
      ]
    }
  ]
  name "pink object 3"
  boundingObject USE CYLINDER_SHAPE
}
DEF ROBOT Robot {
  translation -1.2702084210777518 0.16620785053655293 -0.0001176898416612171
  rotation 0.016271390413681044 0.016833706592010285 -0.9997258965218314 1.5358832855480655
  children [
    Pose {
      translation 0 0 0.1245
      rotation 0 0 1 -1.570796
      children [
        Shape {
          appearance PBRAppearance {
            baseColor 0.74902 0.74902 0.74902
            roughness 1
            metalness 0
          }
          geometry DEF BODY Cylinder {
            height 0.24
            radius 0.135
          }
        }
      ]
    }
    HingeJoint {
      jointParameters HingeJointParameters {
        position 1364.2347528695004
        axis 0 1 0
        anchor 0 0 0.075
      }
      device [
        RotationalMotor {
          name "left wheel motor"
          consumptionFactor 70
          maxVelocity 100
        }
        PositionSensor {
          name "left wheel sensor"
        }
      ]
      endPoint Solid {
        translation 0 0.135 0.075
        rotation 0.24514027508471167 -0.24514037242828987 0.9379831786002941 4.648409661237858
        children [
          DEF WHEEL Pose {
            rotation 0.577656895078166 0.5771968951617173 -0.5771968951617173 -2.093935
            children [
              Shape {
                appearance PBRAppearance {
                  baseColor 0.301961 0.301961 0.301961
                  roughness 1
                  metalness 0
                }
                geometry Cylinder {
                  height 0.03
                  radius 0.075
                }
              }
            ]
          }
        ]
        name "left wheel"
        boundingObject USE WHEEL
        physics DEF PHYSICS_WHEEL Physics {
          density -1
          mass 0.05
        }
        linearVelocity 0.0149442386291259 -0.4327122260868583 9.30807516572512e-06
        angularVelocity 5.739499176863272 0.1982623470290541 0.15090139873962224
      }
    }
    HingeJoint {
      jointParameters HingeJointParameters {
        position 1219.027661508836
        axis 0 1 0
        anchor 0 0 0.075
      }
      device [
        RotationalMotor {
          name "right wheel motor"
          consumptionFactor 70
          maxVelocity 100
        }
        PositionSensor {
          name "right wheel sensor"
        }
      ]
      endPoint Solid {
        translation 0 -0.1350000000000001 0.075
        rotation -0.10655887884411953 0.10655887487998789 -0.9885799975337329 1.5822818750352987
        children [
          USE WHEEL
        ]
        name "right wheel"
        boundingObject USE WHEEL
        physics USE PHYSICS_WHEEL
        linearVelocity 0.016346595393133326 -0.4731998262565098 -6.7050518355014e-06
        angularVelocity 6.339107851080183 0.21894021375797687 0.15104928826298453
      }
    }
    DEF US0 DistanceSensor {
      translation 0.115 0.07 0.189
      rotation 0 0 -1 -0.499205
      children [
        DEF SONAR_SENSOR Pose {
          rotation 0.577656895078166 0.5771968951617173 -0.5771968951617173 -2.093935
          children [
            Shape {
              appearance PBRAppearance {
                baseColor 0.301961 0.301961 0.301961
                roughness 1
                metalness 0
              }
              geometry Cylinder {
                height 0.01
                radius 0.024
              }
            }
          ]
        }
      ]
      name "us0"
      lookupTable [
        0 0.7 0.01
        2 0 0
      ]
      type "sonar"
      numberOfRays 20
    }
    DEF US1 DistanceSensor {
      translation 0.115 -0.07 0.189
      rotation 0 0 1 -0.500795
      children [
        USE SONAR_SENSOR
      ]
      name "us1"
      lookupTable [
        0 0.7 0.1
        2 0 0
      ]
      type "sonar"
      numberOfRays 20
    }
    DEF LIDAR Lidar {
      translation 0 0 0.45
      children [
        Transform {
          translation 0 0 -0.01
          rotation 0 0 -1 1.570796
          scale 6 5 3
          children [
            DEF STRUCTURE_AXES Shape {
              appearance Appearance {
                material Material {
                  diffuseColor 0.02 0.02 0.02
                }
              }
              geometry IndexedLineSet {
                coord Coordinate {
                  point [
                    0 0 0.01
                    0.01 0 -0.08
                    -0.01 0 -0.08
                    0 0.01 -0.08
                    0 -0.01 -0.08
                  ]
                }
                coordIndex [
                  0, 1, 0, 2, 0, 3, 0, 4
                ]
              }
            }
          ]
        }
      ]
      tiltAngle -0.1
      horizontalResolution 256
      fieldOfView 1.57
      numberOfLayers 6
      near 0.05
      minRange 0.05
      maxRange 8
      type "rotating"
      noise 0.1
      defaultFrequency 2
      rotatingHead Solid {
        rotation 0 0 1 0.7037167544041274
        children [
          Pose {
            translation 0.03 0 0
            rotation 0 0 1 3.14159
            children [
              DEF LENS Shape {
                appearance PBRAppearance {
                  baseColor 0 0 0
                  roughness 1.1102230246251565e-16
                  metalness 0
                }
                geometry Sphere {
                  radius 0.015
                  subdivision 2
                }
              }
            ]
          }
          DEF CAMERA_SHAPE Pose {
            rotation -0.5771978956908259 0.5776548956082386 0.5771978956908259 -2.093935
            children [
              DEF CAMERA_OUTLINE Shape {
                appearance PBRAppearance {
                  baseColor 0.898039 0.898039 0.898039
                  roughness 1
                  metalness 0
                }
                geometry Cylinder {
                  height 0.06
                  radius 0.024
                }
              }
            ]
          }
        ]
      }
    }
  ]
  name "MyBot"
  boundingObject Pose {
    translation 0 0 0.1245
    rotation 0 0 1 -1.570796
    children [
      USE BODY
    ]
  }
  physics Physics {
    density -1
    mass 1.5
    centerOfMass [
      0 0 0.15
    ]
  }
  controller "lidar_informationextraction"
  linearVelocity 0.016006250475721823 -0.45294831930905444 9.25834632335397e-07
  angularVelocity 5.188191770254184e-05 -6.795053641513249e-05 0.15008151836590874
}
